2022-04-11 14:30:12,569 INFO    MainThread:34216 [internal.py:wandb_internal():92] W&B internal server running at pid: 34216, started at: 2022-04-11 14:30:12.569098
2022-04-11 14:30:12,573 INFO    WriterThread:34216 [datastore.py:open_for_write():77] open: /home/lechapelier/Documents/Stage M2/moral_rl/moral/wandb/run-20220411_143011-ucpmd2j1/run-ucpmd2j1.wandb
2022-04-11 14:30:12,575 DEBUG   SenderThread:34216 [sender.py:send():235] send: header
2022-04-11 14:30:12,576 DEBUG   SenderThread:34216 [sender.py:send():235] send: run
2022-04-11 14:30:15,695 ERROR   SenderThread:34216 [retry.py:__call__():126] Retry attempt failed:
Traceback (most recent call last):
  File "/usr/lib/python3/dist-packages/urllib3/connection.py", line 169, in _new_conn
    conn = connection.create_connection(
  File "/usr/lib/python3/dist-packages/urllib3/util/connection.py", line 73, in create_connection
    for res in socket.getaddrinfo(host, port, family, socket.SOCK_STREAM):
  File "/usr/lib/python3.9/socket.py", line 953, in getaddrinfo
    for res in _socket.getaddrinfo(host, port, family, type, proto, flags):
socket.gaierror: [Errno -2] Name or service not known

During handling of the above exception, another exception occurred:

Traceback (most recent call last):
  File "/usr/lib/python3/dist-packages/urllib3/connectionpool.py", line 699, in urlopen
    httplib_response = self._make_request(
  File "/usr/lib/python3/dist-packages/urllib3/connectionpool.py", line 382, in _make_request
    self._validate_conn(conn)
  File "/usr/lib/python3/dist-packages/urllib3/connectionpool.py", line 1012, in _validate_conn
    conn.connect()
  File "/usr/lib/python3/dist-packages/urllib3/connection.py", line 353, in connect
    conn = self._new_conn()
  File "/usr/lib/python3/dist-packages/urllib3/connection.py", line 181, in _new_conn
    raise NewConnectionError(
urllib3.exceptions.NewConnectionError: <urllib3.connection.HTTPSConnection object at 0x7ff75cae1fa0>: Failed to establish a new connection: [Errno -2] Name or service not known

During handling of the above exception, another exception occurred:

Traceback (most recent call last):
  File "/usr/lib/python3/dist-packages/requests/adapters.py", line 439, in send
    resp = conn.urlopen(
  File "/usr/lib/python3/dist-packages/urllib3/connectionpool.py", line 755, in urlopen
    retries = retries.increment(
  File "/usr/lib/python3/dist-packages/urllib3/util/retry.py", line 574, in increment
    raise MaxRetryError(_pool, url, error or ResponseError(cause))
urllib3.exceptions.MaxRetryError: HTTPSConnectionPool(host='api.wandb.ai', port=443): Max retries exceeded with url: /graphql (Caused by NewConnectionError('<urllib3.connection.HTTPSConnection object at 0x7ff75cae1fa0>: Failed to establish a new connection: [Errno -2] Name or service not known'))

During handling of the above exception, another exception occurred:

Traceback (most recent call last):
  File "/home/lechapelier/.local/lib/python3.9/site-packages/wandb/sdk/lib/retry.py", line 102, in __call__
    result = self._call_fn(*args, **kwargs)
  File "/home/lechapelier/.local/lib/python3.9/site-packages/wandb/sdk/internal/internal_api.py", line 141, in execute
    return self.client.execute(*args, **kwargs)
  File "/home/lechapelier/.local/lib/python3.9/site-packages/wandb/vendor/gql-0.2.0/wandb_gql/client.py", line 52, in execute
    result = self._get_result(document, *args, **kwargs)
  File "/home/lechapelier/.local/lib/python3.9/site-packages/wandb/vendor/gql-0.2.0/wandb_gql/client.py", line 60, in _get_result
    return self.transport.execute(document, *args, **kwargs)
  File "/home/lechapelier/.local/lib/python3.9/site-packages/wandb/vendor/gql-0.2.0/wandb_gql/transport/requests.py", line 38, in execute
    request = requests.post(self.url, **post_args)
  File "/usr/lib/python3/dist-packages/requests/api.py", line 119, in post
    return request('post', url, data=data, json=json, **kwargs)
  File "/usr/lib/python3/dist-packages/requests/api.py", line 61, in request
    return session.request(method=method, url=url, **kwargs)
  File "/usr/lib/python3/dist-packages/requests/sessions.py", line 542, in request
    resp = self.send(prep, **send_kwargs)
  File "/usr/lib/python3/dist-packages/requests/sessions.py", line 655, in send
    r = adapter.send(request, **kwargs)
  File "/usr/lib/python3/dist-packages/requests/adapters.py", line 516, in send
    raise ConnectionError(e, request=request)
requests.exceptions.ConnectionError: HTTPSConnectionPool(host='api.wandb.ai', port=443): Max retries exceeded with url: /graphql (Caused by NewConnectionError('<urllib3.connection.HTTPSConnection object at 0x7ff75cae1fa0>: Failed to establish a new connection: [Errno -2] Name or service not known'))
2022-04-11 14:30:41,662 DEBUG   HandlerThread:34216 [handler.py:handle_request():141] handle_request: shutdown
2022-04-11 14:30:41,663 INFO    HandlerThread:34216 [handler.py:finish():790] shutting down handler
2022-04-11 14:30:42,580 INFO    WriterThread:34216 [datastore.py:close():281] close: /home/lechapelier/Documents/Stage M2/moral_rl/moral/wandb/run-20220411_143011-ucpmd2j1/run-ucpmd2j1.wandb
2022-04-11 14:30:46,057 INFO    SenderThread:34216 [dir_watcher.py:__init__():169] watching files in: /home/lechapelier/Documents/Stage M2/moral_rl/moral/wandb/run-20220411_143011-ucpmd2j1/files
2022-04-11 14:30:46,057 INFO    SenderThread:34216 [sender.py:_start_run_threads():812] run started: ucpmd2j1 with start time 1649680211
2022-04-11 14:30:46,057 INFO    SenderThread:34216 [sender.py:finish():1107] shutting down sender
2022-04-11 14:30:46,057 INFO    SenderThread:34216 [dir_watcher.py:finish():283] shutting down directory watcher
2022-04-11 14:30:47,059 INFO    SenderThread:34216 [dir_watcher.py:finish():313] scan: /home/lechapelier/Documents/Stage M2/moral_rl/moral/wandb/run-20220411_143011-ucpmd2j1/files
2022-04-11 14:30:47,060 INFO    SenderThread:34216 [dir_watcher.py:finish():327] scan save: /home/lechapelier/Documents/Stage M2/moral_rl/moral/wandb/run-20220411_143011-ucpmd2j1/files/config.yaml config.yaml
2022-04-11 14:30:47,060 INFO    SenderThread:34216 [file_pusher.py:finish():145] shutting down file pusher
2022-04-11 14:30:47,061 INFO    SenderThread:34216 [file_pusher.py:join():150] waiting for file pusher
2022-04-11 14:30:47,695 INFO    Thread-9  :34216 [upload_job.py:push():137] Uploaded file /home/lechapelier/Documents/Stage M2/moral_rl/moral/wandb/run-20220411_143011-ucpmd2j1/files/config.yaml
2022-04-11 14:30:48,499 INFO    MainThread:34216 [internal.py:handle_exit():82] Internal process exited
